<?xml version="1.0" encoding="UTF-8"?>
<testsuite errors="1" failures="0" file="unittest/loader.py" name="unittest.loader._FailedTest-20190807081325"
           skipped="0" tests="1" time="0.004" timestamp="2019-08-07T08:14:40">
    <testcase classname="unittest.loader._FailedTest" file="/usr/lib/python3.7/unittest/loader.py" line="33"
              name="test_python_simulation" time="0.004" timestamp="2019-08-07T08:14:40">
        <error message="Failed to import test module: test_python_simulation
Traceback (most recent call last):
  File &quot;/usr/lib/python3.7/unittest/loader.py&quot;, line 154, in loadTestsFromName
    module = __import__(module_name)
  File &quot;/home/clinton/development/work/idmtools/idmtools_platform_local/tests/test_python_simulation.py&quot;, line 2, in &lt;module&gt;
    from idmtools_test.utils.confg_local_runner_test import config_local_rest
ImportError: cannot import name 'config_local_rest' from 'idmtools_test.utils.confg_local_runner_test' (/home/clinton/development/work/idmtools/idmtools_test/idmtools_test/utils/confg_local_runner_test.py)
" type="ImportError">
            <![CDATA[ImportError: Failed to import test module: test_python_simulation
Traceback (most recent call last):
  File "/usr/lib/python3.7/unittest/loader.py", line 154, in loadTestsFromName
    module = __import__(module_name)
  File "/home/clinton/development/work/idmtools/idmtools_platform_local/tests/test_python_simulation.py", line 2, in <module>
    from idmtools_test.utils.confg_local_runner_test import config_local_rest
ImportError: cannot import name 'config_local_rest' from 'idmtools_test.utils.confg_local_runner_test' (/home/clinton/development/work/idmtools/idmtools_test/idmtools_test/utils/confg_local_runner_test.py)

]]>        </error>
        <system-out>
            <![CDATA[]]>        </system-out>
        <system-err>
            <![CDATA[]]>        </system-err>
    </testcase>
</testsuite>
